<?xml version='1.0'?>

<robot name="my_robot" xmlns:xacro="http://www.ros.org/wiki/xacro">
  <xacro:include filename="$(find my_robot)/urdf/my_robot.gazebo" />	
  <link name="robot_footprint"></link>

  <joint name="robot_footprint_joint" type="fixed">
    <origin xyz="0 0 0" rpy="0 0 0" />
    <parent link="robot_footprint"/>
    <child link="chassis" />
  </joint>

  <link name='chassis'>
    <pose>0 0 0.1 0 0 0</pose>

    <inertial>
      <mass value="15.0"/>
      <origin xyz="0.0 0 0" rpy=" 0 0 0"/>
      <inertia
          ixx="0.1" ixy="0" ixz="0"
          iyy="0.1" iyz="0"
          izz="0.1"
      />
    </inertial>

    <collision name='collision'>
      <origin xyz="0 0 0" rpy=" 0 0 0"/> 
      <geometry>
        <box size=".4 .2 .1"/>
      </geometry>
    </collision>

    <visual name='chassis_visual'>
      <origin xyz="0 0 0" rpy=" 0 0 0"/>
      <geometry>
        <box size=".4 .2 .1"/>
      </geometry>
    </visual>


  </link>

  <!--left_wheel-->  
  <link name='front_left_wheel'>    
    <inertial>
      <mass value="5"/>
      <origin xyz="0 0 0" rpy="0 1.5707 1.5707" />
      <inertia
          ixx="0.1" ixy="0" ixz="0"
          iyy="0.1" iyz="0"
          izz="0.1"
      />
    </inertial>
    
    <collision name='front_left_wheel_collision'>
      <origin  xyz="0 0 0" rpy="0 1.5707 1.5707"/>
      <geometry>
        <cylinder length="0.05" radius="0.1"/>
      </geometry>
    </collision>
    
    <visual name='front_left_wheel_visual'>
      <origin xyz="0 0 0" rpy="0 1.5707 1.5707"/>
      <geometry>
        <cylinder length="0.05" radius="0.1"/>
      </geometry> 
    </visual>
    
  </link> 
  
  <link name='rear_left_wheel'>    
    <inertial>
      <mass value="5"/>
      <origin xyz="0 0 0" rpy="0 1.5707 1.5707" />
      <inertia
          ixx="0.1" ixy="0" ixz="0"
          iyy="0.1" iyz="0"
          izz="0.1"
      />
    </inertial>
    
    <collision name='rear_left_wheel_collision'>
      <origin  xyz="0 0 0" rpy="0 1.5707 1.5707"/>
      <geometry>
        <cylinder length="0.05" radius="0.1"/>
      </geometry>
    </collision>
    
    <visual name='rear_left_wheel_visual'>
      <origin xyz="0 0 0" rpy="0 1.5707 1.5707"/>
      <geometry>
        <cylinder length="0.05" radius="0.1"/>
      </geometry> 
    </visual>
    
  </link> 

  <!--right_wheel-->  
  <link name='front_right_wheel'>    
    <inertial>
      <mass value="5"/>
      <origin xyz="0 0 0" rpy="0 1.5707 1.5707" />
      <inertia
          ixx="0.1" ixy="0" ixz="0"
          iyy="0.1" iyz="0"
          izz="0.1"
      />
    </inertial>
    
    <collision name='front_right_wheel_collision'>
      <origin  xyz="0 0 0" rpy="0 1.5707 1.5707"/>
      <geometry>
        <cylinder length="0.05" radius="0.1"/>
      </geometry>
    </collision>
    
    <visual name='front_right_wheel_visual'>
      <origin xyz="0 0 0" rpy="0 1.5707 1.5707"/>
      <geometry>
        <cylinder length="0.05" radius="0.1"/>
      </geometry>  
    </visual>
  
  </link>

  <link name='rear_right_wheel'>    
    <inertial>
      <mass value="5"/>
      <origin xyz="0 0 0" rpy="0 1.5707 1.5707" />
      <inertia
          ixx="0.1" ixy="0" ixz="0"
          iyy="0.1" iyz="0"
          izz="0.1"
      />
    </inertial>
    
    <collision name='rear_right_wheel_collision'>
      <origin  xyz="0 0 0" rpy="0 1.5707 1.5707"/>
      <geometry>
        <cylinder length="0.05" radius="0.1"/>
      </geometry>
    </collision>
    
    <visual name='rear_right_wheel_visual'>
      <origin xyz="0 0 0" rpy="0 1.5707 1.5707"/>
      <geometry>
        <cylinder length="0.05" radius="0.1"/>
      </geometry>  
    </visual>
  
  </link>
  <!--left_wheel_hinge-->
  <joint name="front_left_wheel_hinge" type="continuous">
    <origin xyz="0.15 0.125 0" rpy="0 0 0"/>
    <child link="front_left_wheel" />
    <parent link="chassis"/>
    <axis xyz="0 1 0" rpy="0 0 0" />
    <limit effort="10000" velocity="1000"/>
    <joint_properties damping="1.0" friction="1.0" />
  </joint>

  <joint name="rear_left_wheel_hinge" type="continuous">
    <origin xyz="-0.15 0.125 0" rpy="0 0 0"/>
    <child link="rear_left_wheel" />
    <parent link="chassis"/>
    <axis xyz="0 1 0" rpy="0 0 0" />
    <limit effort="10000" velocity="1000"/>
    <joint_properties damping="1.0" friction="1.0" />
  </joint>
  
  <!--right_wheel_hinge-->
  <joint name="front_right_wheel_hinge" type="continuous">
    <origin xyz="0.15 -0.125 0" rpy="0 0 0"/>
    <child link="front_right_wheel" />
    <parent link="chassis"/>
    <axis xyz="0 1 0" rpy="0 0 0" />
    <limit effort="10000" velocity="1000"/>
    <joint_properties damping="1.0" friction="1.0" />
  </joint>

  <joint name="rear_right_wheel_hinge" type="continuous">
    <origin xyz="-0.15 -0.125 0" rpy="0 0 0"/>
    <child link="rear_right_wheel" />
    <parent link="chassis"/>
    <axis xyz="0 1 0" rpy="0 0 0" />
    <limit effort="10000" velocity="1000"/>
    <joint_properties damping="1.0" friction="1.0" />
  </joint>

  <!--Camera-->  
  <link name='camera'>    
    <inertial>
      <mass value="0.1"/>
      <origin xyz="0 0 0" rpy="0 0 0" />
      <inertia
          ixx="1e-6" ixy="0" ixz="0"
          iyy="1e-6" iyz="0"
          izz="1e-6"
      />
      <box_inertia m="0.1" x="0.05" y="0.05" z="0.05"/>
    </inertial>
    
    <collision name='camera_collision'>
      <origin xyz="0 0 0" rpy="0 0 0" />
      <geometry>
        <box size="0.05 0.05 0.05"/>
      </geometry>
    </collision>
    
    <visual name='camera_visual'>
      <origin xyz="0 0 0" rpy="0 0 0" />
      <geometry>
        <box size="0.05 0.05 0.05"/>
      </geometry>
    </visual>
  
  </link>

  <!--camera joint-->
  <joint name="camera_joint" type="fixed">
    <origin xyz="0.2 0 0" rpy="0 0 0"/>
    <child link="camera" />
    <parent link="chassis"/>
    <axis xyz="0 1 0" rpy="0 0 0" />
   </joint>

  <!--Lidar-->  
  <link name='hokuyo'>    
    <inertial>
      <mass value="1e-5"/>
      <origin xyz="0 0 0" rpy="0 0 0" />
      <inertia
          ixx="1e-6" ixy="0" ixz="0"
          iyy="1e-6" iyz="0"
          izz="1e-6"
      />
    </inertial>
    
    <collision name='hokuyo_collision'>
      <origin xyz="0 0 0" rpy="0 0 0" />
      <geometry>
        <box size="0.1 0.1 0.1"/>
      </geometry>
    </collision>
    
    <visual name='hokuyo_visual'>
      <origin xyz="0 0 0" rpy="0 0 0" />
      <geometry>
	 <mesh filename="package://my_robot/meshes/hokuyo.dae"/>       
	
      </geometry>
    </visual>
  
  </link>

  <!--lidar joint-->
  <joint name="hokuyo_joint" type="fixed">
    <origin xyz="0.15 0 0.1" rpy="0 0 0"/>
    <child link="hokuyo" />
    <parent link="chassis"/>
    <axis xyz="0 1 0" rpy="0 0 0" />
   </joint>

<gazebo reference="front_left_wheel">
    <material>Gazebo/Green</material>
</gazebo>

<gazebo reference="front_right_wheel">
    <material>Gazebo/Green</material>
</gazebo>

<gazebo reference="chassis">
    <material>Gazebo/Blue</material>
</gazebo>


<gazebo reference="camera">
    <material>Gazebo/Red</material>
</gazebo>

</robot>


